<mujoco model="Humanoid">
	<!--  Copyright © 2018, Roboti LLC

          This file is licensed under the MuJoCo Resource License (the "License").
          You may not use this file except in compliance with the License.
          You may obtain a copy of the License at

            https://www.roboti.us/resourcelicense.txt
    -->

	<compiler inertiafromgeom="true" angle="degree"/>

	<default>
		<joint limited="true" damping="10" armature="0"/>
		<geom condim="1" material="matgeom"/>
	</default>

	<option timestep="0.002" iterations="50" tolerance="1e-10" solver="Newton" jacobian="dense" cone="pyramidal"/>
	<size nconmax="500" njmax="2000" nstack="10000"/>

	<visual>
		<map force="0.1" zfar="30"/>
		<rgba haze="0.15 0.25 0.35 1" contactfriction =" 0.9 0.8 0.4 1"/>
		<quality shadowsize="2048"/>
		<global offwidth="800" offheight="800"/>
	</visual>


	<asset>
		<texture type="skybox" builtin="gradient" rgb1="0.3 0.5 0.7" rgb2="0 0 0" width="512" height="512"/>
		<texture name="texplane" type="2d" builtin="checker" rgb1=".2 .3 .4" rgb2=".1 0.15 0.2" width="512" height="512" mark="cross" markrgb=".8 .8 .8"/>
		<texture name="texgeom" type="cube" builtin="flat" mark="cross" width="127" height="1278"
            rgb1 ="0.65 0.65 0.65" rgb2="0.65 0.65 0.65" markrgb="1 1 1" random="0.01"/>
		<material name="matplane" reflectance="0.3" texture="texplane" texrepeat="1 1" texuniform="true"/>
		<material name="matgeom"  rgba =" 1.0 1.0 1.0 1 "  texture="texgeom"  texuniform="true" />
	</asset>

	<worldbody>
		<geom name="floor" pos="0 0 0" size="0 0 .25" type="plane" material="matplane" condim="3"/>
		<light directional="false" diffuse=".2 .2 .2" specular="0 0 0" pos="0 0 5" dir="0 0 -1" castshadow="false"/>
		<body name="body0" pos="0.0 0.0 0.86" >
			<body name="link1" pos="0.08 0.0 0.70 " >
				<joint name ="position1" type ="slide" pos="-0.175 0.0 0.0" axis="0 0 1" range="-5.0 5.0" frictionloss="0" damping="0"  />
				<joint name="motor1" type="hinge" pos="-0.175 0.0 0.0" axis="0 0 1" range="-3600 3600" damping="10" stiffness="0" armature="0.0" />
				<geom name	="geo1" type="box"  size="0.175 0.04 0.025" rgba="1.0 1.0 0.0 1"/>
				<geom name ="geo1_end1" type ="cylinder" pos =" 0.175 0.0 0.0" size ="0.04 0.025" rgba="1.0 1.0 0.0 1"/>
				<geom name ="geo1_end2" type ="cylinder" pos =" -0.175 0.0 0.0" size ="0.04 0.025" rgba="1.0 1.0 0.0 1"/>
				<inertial pos="0 0 0" mass="1" diaginertia="0.16 0.16 0.16"/>
				<body name="link2" pos="0.35 0.0 0.03" >
					<joint name="motor2" type="hinge" pos="-0.175 0.0 0.0" axis="0 0 1" range ="-3600 3600 "  damping="10" stiffness="0" armature="0.0" />
					<geom name	="geo2" type="box"  size="0.175 0.04 0.025" rgba="1.0 1.0 0.0 1"/>
					<geom name ="geo2_end1" type ="cylinder" pos =" 0.175 0.0 0.0" size ="0.04 0.025" rgba="1.0 1.0 0.0 1"/>
					<geom name ="geo2_end2" type ="cylinder" pos =" -0.175 0.0 0.0" size ="0.04 0.025" rgba="1.0 1.0 0.0 1"/>
					<inertial pos="0 0 0" mass="1" diaginertia="0.16 0.16 0.16"/>
					<body name="link3" pos="0.175 0.0 0.03"  >
						<joint name="motor3" type="hinge" pos="0.0 0.0 0.0" axis="0 0 1"  range="-3600 3600" damping="10" stiffness="0.0" armature="0.0"  />
						<geom name	="geo3" type="box"  size="0.02 0.05 0.015" rgba="1.0 1.0 0.0 1" />
						<geom name ="geo3_end1" type ="cylinder" pos =" 0.0 0.0 0.0" condim ="1" size ="0.04 0.015"  friction ="  10.0 10.0 10.0 " rgba="1.0 1.0 0.0 1"/>
						<geom name ="geo3_end2" type ="box" pos =" 0.0 0.0 0.0"  size ="0.15 0.125 0.015"  friction ="  10.0 10.0 10.0 " rgba="1.0 1.0 0.0 1" />
						<!-- 테스트 확인용 -->
						<geom name ="geo3_end3" type ="cylinder" pos =" 0.11 0.0 0.0" condim ="1" size ="0.02 0.016"  friction ="  10.0 10.0 10.0 " rgba="1.0 0.0 0.0 1" />

						<inertial pos="0.0 0.0 0.0" mass="1" diaginertia="0.16 0.16 0.16"/>
					</body>
				</body>
			</body>
		</body>

		<body name="body1" pos="-0.51 0.0 1.52" >
			<geom name	="geo4_4thfloor" type="box"  size="0.37 0.30 0.02" rgba =" 1.3 1.3 1.3 1" />
			<body name="body2" pos="0.0 0.0 -0.3" >
				<geom name	="geo4_3rdfloor" type="box"  size="0.37 0.30 0.02" rgba =" 1.3 1.3 1.3 1"/>
				<geom name ="geo4_3ndfloor_1" type="box" pos ="0.225 0.05 0.04" size ="0.135 0.02 0.02 " rgba =" 1.5 1.5 1.5 1"></geom>
				<geom name ="geo4_3ndfloor_2" type="box" pos ="0.225 0.25 0.04" size ="0.135 0.02 0.02" rgba =" 1.5 1.5 1.5 1"></geom>
				<geom name ="geo4_3ndfloor_3" type="box" pos ="0.225 -0.05 0.04" size ="0.135 0.02 0.02 " rgba =" 1.5 1.5 1.5 1"></geom>
				<geom name ="geo4_3ndfloor_4" type="box" pos ="0.225 -0.25 0.04" size ="0.135 0.02 0.02 " rgba =" 1.5 1.5 1.5 1"></geom>
				<body name="body3" pos="0.0 0.0 -0.3" >
					<geom name	="geo4_2ndfloor" type="box"  size="0.37 0.30 0.02" rgba =" 1.3 1.3 1.3  1"/>
					<geom name ="geo4_2ndfloor_1" type="box" pos ="0.225 0.05 0.04"  size ="0.135 0.02 0.02 " rgba =" 1.5 1.5 1.5 1"></geom>
					<geom name ="geo4_2ndfloor_2" type="box" pos ="0.225 0.25 0.04"  size ="0.135 0.02 0.02 " rgba =" 1.5 1.5 1.5 1"></geom>
					<geom name ="geo4_2ndfloor_3" type="box" pos ="0.225 -0.05 0.04" size ="0.135 0.02 0.02 " rgba =" 1.5 1.5 1.5 1"></geom>
					<geom name ="geo4_2ndfloor_4" type="box" pos ="0.225 -0.25 0.04" size ="0.135 0.02 0.02 " rgba =" 1.5 1.5 1.5 1"></geom>


					<body name="body4" pos="0.0 0.0 -0.54" >
						<geom name	="geo4_1stfloor" type="box"  size="0.37 0.30 0.28" rgba="2.0 1.0 0.0 1"/>
						<body name="body5" pos="0.0 0.0 0.71" >
							<geom name	="geo4_center" type="box"  size="0.15 0.01 0.4" rgba="2.0 1.0 0.0 1"  />
							<body name="body6" pos="0.0 0.0 0.0" >
								<geom name	="geo4_center2" type="box"  size="0.01 0.10 0.4" rgba="2.0 1.0 0.0 1"  />
								<body name="body8" pos="0.25 -0.40 -1.04" >
									<geom name	="geo4_wheel1" type="cylinder" size="0.05 0.01"  fromto ="0 0.1 0 0 0.2 0" rgba="2.0 1.0 0.0 1"/>
									<geom name	="geo4_wheel2" type="cylinder" size="0.05 0.01" fromto ="-0.5 0.1 0 -0.5 0.2 0" rgba="2.0 1.0 0.0 1"/>
									<geom name	="geo4_wheel3" type="cylinder" size="0.05 0.01"  fromto ="-0.5 0.58 0 -0.5 0.68 0" rgba="2.0 1.0 0.0 1"/>
									<geom name	="geo4_wheel4" type="cylinder" size="0.05 0.01"  fromto ="0 0.58 0 0 0.68 0" rgba="2.0 1.0 0.0 1"/>

								</body>
							</body>
						</body>
					</body>
				</body>
			</body>
		</body>

		<body name="table" pos="-0.36 0.6 0.44" >
			<geom name	="table" type="box"  size="0.25 0.15 0.46"  condim ="1"  friction ="1 0.006 0.0001" rgba="2.0 1.0 0.0 1" />
			<geom name	="table_1" type="box"  size ="0.25 0.01 0.02 " condim ="1"  pos="0 0.13 0.48" friction ="1 1 1" rgba="2.0 1.0 0.0 1"/>
			<geom name	="table_2" type="box"  size ="0.25 0.01 0.02 " condim ="1"  pos="0 -0.13 0.48" friction ="1 1 1" rgba="2.0 1.0 0.0 1"/>

		</body>

		<body name="table2" pos="-0.36 -0.6 0.26" >
			<geom name	="table2" type="box"  size="0.25 0.15 0.46"  condim ="1"  friction ="1 0.006 0.0001" rgba="2.0 1.0 0.0 1" />
			<geom name	="table_12" type="box"  size ="0.25 0.01 0.02 " condim ="1"  pos="0 0.13 0.48" friction ="1 1 1" rgba="2.0 1.0 0.0 1"/>
			<geom name	="table_22" type="box"  size ="0.25 0.01 0.02 " condim ="1"  pos="0 -0.13 0.48" friction ="1 1 1" rgba="2.0 1.0 0.0 1"/>

		</body>

		<body pos="-0.30 0.15 1.00" >
			<freejoint/>
			<geom name ="tray1" type="box"  size="0.15 0.125 0.02" rgba="1.0 0.0 0.0 1" condim ="1" friction ="10.0 10.0 10.0" gap ="0" margin ="0.0" />
			<geom name ="tray11" type="box"  size="0.15 0.125 0.02" rgba="1.0 0.0 0.0 1" condim ="3" friction ="10.0 10.0 10.0" gap ="0" margin ="0.0" />
			<inertial pos="0.0 0.0 0.0" mass="0.5" diaginertia="0.01 0.01 0.01"  />
		</body>

		<body pos="-0.30 -0.15 1.00" >
			<freejoint/>
			<geom name ="tray2" type="box"  size="0.15 0.125 0.02" rgba="1.0 0.0 0.0 1" condim ="1" friction ="10.0 10.0 10.0" gap ="0" margin ="0.0" />
			<geom name ="tray22" type="box"  size="0.15 0.125 0.02" rgba="1.0 0.0 0.0 1" condim ="3" friction ="10.0 10.0 10.0" gap ="0" margin ="0.0" />
			<inertial pos="0.0 0.0 0.0" mass="0.5" diaginertia="0.01 0.01 0.01"  />
		</body>

		<body pos="-0.30 0.15 1.30" >
			<freejoint/>
			<geom name ="tray3" type="box"  size="0.15 0.125 0.02" rgba="1.0 0.0 0.0 1" condim ="1" friction ="10.0 10.0 10.0" gap ="0" margin ="0.0" />
			<geom name ="tray33" type="box"  size="0.15 0.125 0.02" rgba="1.0 0.0 0.0 1" condim ="3" friction ="10.0 10.0 10.0" gap ="0" margin ="0.0" />
			<inertial pos="0.0 0.0 0.0" mass="0.5" diaginertia="0.01 0.01 0.01"  />
		</body>

		<body pos="-0.30 -0.15 1.30" >
			<freejoint/>
			<geom name ="tray4" type="box"  size="0.15 0.125 0.02" rgba="1.0 0.0 0.0 1" condim ="1" friction ="10.0 10.0 10.0" gap ="0" margin ="0.0" />
			<geom name ="tray44" type="box"  size="0.15 0.125 0.02" rgba="1.0 0.0 0.0 1" condim ="3" friction ="10.0 10.0 10.0" gap ="0" margin ="0.0" />
			<inertial pos="0.0 0.0 0.0" mass="0.5" diaginertia="0.01 0.01 0.01"  />
		</body>

	</worldbody>

	<!-- 있어야 tray가 운반 가능하다고 하나 없어도 작동함. but 운동 관성으로 인해 약간의 미끄러짐이 발생.
	
<contact>
	<pair geom1 ="tray" geom2 ="geo3_end2" friction =" 1.0 1.0 1.0 1.0 1.0" condim ="3" margin =" 0.0" />
	<pair geom1 ="tray" geom2 ="geo3_end3" friction =" 1.0 1.0 1.0 1.0 1.0" condim ="3" margin =" 0.0" />
</contact>


	<contact>
		
		<pair geom1 ="tray1" geom2 ="geo4_2ndfloor_1" friction =" 1.0 1.0 1.0 1.0 1.0" condim ="3" margin =" 0.0" />
		<pair geom1 ="tray1" geom2 ="geo4_2ndfloor_2" friction =" 1.0 1.0 1.0 1.0 1.0" condim ="3" margin =" 0.0" />

		<pair geom1 ="tray2" geom2 ="geo4_2ndfloor_3" friction =" 1.0 1.0 1.0 1.0 1.0" condim ="3" margin =" 0.0" />
		<pair geom1 ="tray2" geom2 ="geo4_2ndfloor_4" friction =" 1.0 1.0 1.0 1.0 1.0" condim ="3" margin =" 0.0" />

		<pair geom1 ="tray3" geom2 ="geo4_3ndfloor_1" friction =" 1.0 1.0 1.0 1.0 1.0" condim ="3" margin =" 0.0" />
		<pair geom1 ="tray3" geom2 ="geo4_3ndfloor_2" friction =" 1.0 1.0 1.0 1.0 1.0" condim ="3" margin =" 0.0" />

		<pair geom1 ="tray4" geom2 ="geo4_3ndfloor_3" friction =" 1.0 1.0 1.0 1.0 1.0" condim ="3" margin =" 0.0" />
		<pair geom1 ="tray4" geom2 ="geo4_3ndfloor_4" friction =" 1.0 1.0 1.0 1.0 1.0" condim ="3" margin =" 0.0" />
		
	</contact>
	
	-->

	<actuator>
		<position name ="position1" joint = "position1"/>
		<motor name="motor1"  gear="100"  joint="motor1" />
		<motor name="motor2"  gear="100"  joint="motor2" />
		<motor name="motor3"  gear="100"  joint="motor3" />

	</actuator>


</mujoco>